Workbook

Sheet Legend
A1: Growth v2 — cost-benefit model
A2: Home Credit PH · 1,113 employees · 3-year horizon · prepared 31 August 2026 · benefit side revised 11 September 2026
A4: HOW TO USE THIS WORKBOOK
A6: Change inputs here | B6: Assumptions is the only sheet you edit. Every other sheet is formulas that trace back to it.
A7: Blue text | B7: A hardcoded input. Change it.
A8: Yellow fill | B8: A key lever — the assumptions most likely to be challenged, and the ones that move the answer most.
A9: Black text | B9: A formula on the same sheet. Do not overwrite.
A10: Green text | B10: A formula pulling from another sheet. Do not overwrite.
A11: Recalculate | B11: The workbook recalculates on open. If your Excel is set to manual, press F9.
A13: SHEETS
A15: Assumptions | B15: Every input, grouped. The only sheet with hardcoded numbers.
A16: Costs | B16: Build and run, by year. Three-year total cost of ownership.
A17: Competition | B17: v2-lean against the external-platform bands, and the break-even each option implies.
A18: Benefits | B18: Two streams — attributed (needs a confirmed referral) and owned (needs no attribution) — across three scenarios.
A19: CBA | B19: Net, benefit-cost ratio, NPV and payback per scenario, including two stress cases.
A20: Payback | B20: The month-by-month cashflow behind the payback figures on CBA.
A21: Sensitivity | B21: What moves the answer, and by how much.
A23: WHAT THIS MODEL DOES NOT CLAIM
A25: • | B25: Vendor pricing is an RFP planning band derived from how enterprise HR SaaS is structured. It is NOT a quote — none of these vendors publish per-seat pricing. Replace the Competition sheet with real numbers before deciding.
A26: • | B26: The retention lift is a judgement, not a measurement. The v1 dashboard shows 94% retention among participants against 81% company-wide; that 13-point gap is almost certainly selection bias, so it is discounted to 3 points here. The CBA sheet reports the case with this stream removed entirely, because it is the softest input in the model. Since a fill is now priced at TA's actual cost rather than an unsourced P350,000 agency fee, this stream carries most of the case: removing it takes the BCR below 1.
A27: • | B27: Attributed benefits require HC Connect to add a "Growth Marketplace" source value. That commitment does not yet exist. Without it, only the owned stream is defensible.
A28: • | B28: Build effort is a top-down planning estimate. docs/BRD_V2.md carries a bottom-up worksheet for IT; their figure is the authoritative one.
A30: SCOPE OF THIS WORKBOOK — read before quoting a ratio
A31: Costed at 1,113 people (the 637-person pilot plus 476 in mass operations) at P61 = US$1. The three-year cost of P2,049,953 is the headline figure and matches the deck.
A32: The BENEFIT side here counts non-mass participants only, so the base BCR of 3.8 is the CONSERVATIVE case — the deck's "mass-ops benefit excluded" row. The headline BCR of 4.0 adds 54 mass-operations participants at P15,144.06/month basic; see docs/v2-cba-model.py.
A33: Four of the five run lines are bought in dollars and rise as the peso weakens. The P1,785,500 build is peso labour: it moves with neither the exchange rate nor the population.

Sheet Assumptions
A1: Assumptions
A2: Blue = input, edit freely. Yellow = key lever. Sources noted at right.
A4: GLOBAL
A5: Exchange rate | B5: 61 | C5: ₱ / US$1 | D5: As of 8 September 2026. Four of the five run lines are bought in dollars, so a weaker peso RAISES the peso cost of running this. The build is peso labour and does not move.
A6: Population | B6: 1113 | C6: people | D6: The 637-person pilot in IT, Operations and HR, plus 476 in mass operations joining in wave two.
A7: Discount rate | B7: 0.1 | C7: per year | D7: Corporate hurdle rate. Applied to net annual flows in the NPV.
A8: Contingency on build | B8: 0.2 | D8: Applied to build subtotals only, not to run costs.
A9: Horizon | B9: 3 | C9: years | D9: Years. Changing this does not extend the sheets; it is recorded for reference.
A11: LABOUR RATES — fully loaded
A12: Full-stack developer | B12: 150000 | C12: ₱ / month | D12: Planning rate at Philippine market. Validate against your own rate card — this drives the whole build estimate.
A13: Designer | B13: 110000 | C13: ₱ / month
A14: PM / BA | B14: 150000 | C14: ₱ / month
A15: HR analyst | B15: 375 | C15: ₱ / hour | D15: ₱60,000 per month ÷ 160 hours. Used for the reconciliation line only.
A17: BUILD EFFORT — v2-lean
A18: Developer, year 1 | B18: 1.4 | C18: months | D18: Board, matching, JD reader, handoff. Net of lever B (Supabase-native) and lever A (referral engine deferred to year 2).
A19: Designer, year 1 | B19: 1.5 | C19: months | D19: Reduced from 2.5 by reusing the v1 design system already built in the prototype.
A20: Designer allocation | B20: 0.5
A21: PM / BA, year 1 | B21: 4 | C21: months | D21: Includes coordination with recruitment on the HC Connect source field.
A22: PM / BA allocation | B22: 0.3
A23: Security review, DPA assessment, referral-log DPIA | B23: 120000 | C23: ₱ | D23: Raised from v1 by ₱40,000 for the referral-log DPIA. Non-negotiable — it is a launch gate.
A24: Developer, year 2 — deferred referral engine | B24: 0.9 | C24: months | D24: Lever A. Build in Q1 instead if a budget review falls inside the first quarter.
A26: ANNUAL RUN
A27: Supabase Pro + Auth | B27: 25 | C27: US$ / month | D27: Converted at the exchange rate above.
A28: Claude API — Sonnet 5, batched | B28: 40544 | C28: ₱ / year | D28: US$380/yr at 637 people, scaled by headcount and converted at the rate above. 7,686 scoring pairs/month at 1,500 in / 250 out tokens, Batch API at 50% of list.
A29: Transactional email | B29: 15987 | C29: ₱ / year | D29: US$150/yr at 637 people, scaled by headcount. Includes the "did you apply?" nudge — the cheapest line here and the one that converts a click into a countable application.
A30: Monitoring and logging | B30: 7320 | C30: ₱ / year | D30: US$120/yr, converted at the rate above.
A31: Reconciliation effort | B31: 6 | C31: hours / quarter | D31: Quarterly, not monthly, and up from 4 hours with the larger population. Year 2 onward — year 1 has no referral engine to reconcile.
A33: BENEFITS
A34: Avoided hiring cost per internal fill | B34: 17095.24 | C34: ₱ | D34: TA cost-per-hire file, 2025, blended on the mix TA actually hired: 186 Band B at P6,977 and 103 Band C at P35,367. Replaces the P350,000 agency fee carried in earlier drafts, which was cited to the v1 business case and does not appear in it.
A35: Annual basic salary — IT + Operations (non-mass) + HR | B35: 1029634.7 | C35: ₱ | D35: Payroll average monthly basic, September 2026 (P85,802.89) annualised x12. Basic only: the mandatory 13th month and employer contributions are excluded, so the benefit side is stated low. Drives the replacement cost on Benefits.
A36: Replacement cost, as % of salary | B36: 0.75 | D36: Recruitment + ramp + lost output, as a share of annual basic.
A37: Working days per year | B37: 260 | C37: days
A38: Vacancy days saved per internal fill | B38: 37 | C38: days | D38: 21 days to fill internally against 58 externally. Costed on the blended Band B/C salary below, not on the non-mass average.
A39: Gig / DJI / service-offer participants | B39: 120 | C39: per year | D39: Non-mass participants only, 19% of the 637. This workbook therefore reproduces the CONSERVATIVE case in the deck — mass-operations retention benefit excluded, BCR 3.8. docs/v2-cba-model.py adds 54 mass-ops participants at P15,144.06/month basic for the headline BCR 4.0.
A40: Retention lift among participants | B40: 0.03 | C40: points | D40: JUDGEMENT, NOT MEASUREMENT. Observed gap is 13 points (94% vs 81%) and is almost certainly selection bias. Discounted hard. The CBA sheet also reports the case with this set to zero.
A41: Year-1 benefit ramp | B41: 0.4 | D41: Benefits accrue for part of year 1 only, during build and adoption.
A42: Annual basic salary — blended Band B / Band C | B42: 677591.77 | C42: ₱ | D42: Payroll average monthly basic weighted on the 2025 external-hire mix (186 Band B, 103 Band C) = P56,465.98/month, annualised x12. This is the right basis for vacancy days: it is Band B and C roles that internal mobility fills.
A43: SCENARIOS — attributed internal fills per year
A44: Conservative | B44: 2 | C44: fills / year
A45: Base | B45: 4 | C45: fills / year | D45: Roughly one internal fill in fifteen of the ~60 internal requisitions opened a year.
...

Sheet Costs
A1: Costs — v2-lean
A2: Build front-loaded, run flat. Every figure formula-linked to Assumptions.
A4: BUILD — YEAR 1 · our planning estimate (superseded — see IT costing at right) | F4: BUILD — AS COSTED BY IT
A5: Item | B5: Months | C5: Rate (₱/month) | D5: Cost (₱) | F5: Item | G5: Cost (₱)
A6: Full-stack developer — board, matching, JD reader, handoff | B6: =Assumptions!$B$18 | C6: =Assumptions!$B$12 | D6: =B6*C6 | F6: Total build, costed by IT in man-hours | G6: 1785500
A7: Designer — reuses the v1 design system | B7: =Assumptions!$B$19*Assumptions!$B$20 | C7: =Assumptions!$B$13 | D7: =B7*C7 | F7: Year 1 — promotion, matching, JD reader, handoff | G7: 1454200
A8: PM / BA — incl. recruitment coordination on the source field | B8: =Assumptions!$B$21*Assumptions!$B$22 | C8: =Assumptions!$B$14 | D8: =B8*C8 | F8: Year 2 — the deferred referral engine (lever A) | G8: =G6-G7
A9: Security review + DPA assessment + referral-log DPIA | D9: =Assumptions!$B$23 | F9: Phased on the ship-promotion-first plan. Change G6 or G7 and the whole model follows.
A10: Subtotal | D10: =SUM(D6:D9)
A11: Contingency | C11: =Assumptions!$B$8 | D11: =D10*C11
A12: PLANNING ESTIMATE, YEAR 1 | D12: =D10+D11
A14: BUILD — YEAR 2 · our planning estimate (superseded — see IT costing at right)
A15: Item | B15: Months | C15: Rate (₱/month) | D15: Cost (₱)
A16: Full-stack developer — referral engine + attribution reporting | B16: =Assumptions!$B$24 | C16: =Assumptions!$B$12 | D16: =B16*C16
A17: Contingency | C17: =Assumptions!$B$8 | D17: =D16*C17
A18: PLANNING ESTIMATE, YEAR 2 | D18: =D16+D17
A20: ANNUAL RUN
A21: Item | B21: Year 1 (₱) | C21: Year 2+ (₱)
A22: Supabase Pro + Auth | B22: =Assumptions!$B$27*12*Assumptions!$B$5 | C22: =B22
A23: Claude API — Sonnet 5, batched | B23: =Assumptions!$B$28 | C23: =B23
A24: Transactional email, incl. the nudge | B24: =Assumptions!$B$29 | C24: =B24
A25: Monitoring and logging | B25: =Assumptions!$B$30 | C25: =B25
A26: Reconciliation — quarterly, PCD analyst | B26: 0 | C26: =Assumptions!$B$31*4*Assumptions!$B$15
A27: Note: year 1 has no referral engine to reconcile — lever A defers it to year 2.
A28: RUN, PER YEAR | B28: =SUM(B22:B26) | C28: =SUM(C22:C26)
A30: THREE-YEAR TOTAL COST OF OWNERSHIP
B31: Year 1 | C31: Year 2 | D31: Year 3 | E31: 3-year total
A32: Build | B32: =G7 | C32: =G8 | D32: 0 | E32: =SUM(B32:D32)
A33: Run | B33: =B28 | C33: =C28 | D33: =C28 | E33: =SUM(B33:D33)
A34: TOTAL (₱) | B34: =SUM(B32:B33) | C34: =SUM(C32:C33) | D34: =SUM(D32:D33) | E34: =SUM(E32:E33)
A35: TOTAL (US$) | B35: =IFERROR(B34/Assumptions!$B$5,"n/a") | C35: =IFERROR(C34/Assumptions!$B$5,"n/a") | D35: =IFERROR(D34/Assumptions!$B$5,"n/a") | E35: =IFERROR(E34/Assumptions!$B$5,"n/a")
A36: Per employee, 3 years | E36: =IFERROR(E34/Assumptions!$B$6,"n/a")
A37: Per employee, per year | E37: =IFERROR(E34/Assumptions!$B$6/3,"n/a")

Sheet Competition
A1: v2-lean against buying a platform
A2: Bands are RFP planning estimates, NOT quotes. No vendor here publishes per-seat pricing.
A4: EXTERNAL PLATFORM — Gloat, Fuel50, Eightfold, Workday
B5: US$ low | C5: US$ high | D5: ₱ low | E5: ₱ high
A6: Year 1 — licence + implementation + integration | B6: =Assumptions!$B$49+Assumptions!$B$51+Assumptions!$B$53 | C6: =Assumptions!$B$50+Assumptions!$B$52+Assumptions!$B$54 | D6: =B6*Assumptions!$B$5 | E6: =C6*Assumptions!$B$5
A7: Year 2 — licence only | B7: =Assumptions!$B$49 | C7: =Assumptions!$B$50 | D7: =B7*Assumptions!$B$5 | E7: =C7*Assumptions!$B$5
A8: Year 3 — licence only | B8: =Assumptions!$B$49 | C8: =Assumptions!$B$50 | D8: =B8*Assumptions!$B$5 | E8: =C8*Assumptions!$B$5
A9: THREE-YEAR TOTAL | B9: =SUM(B6:B8) | C9: =SUM(C6:C8) | D9: =SUM(D6:D8) | E9: =SUM(E6:E8)
A10: Per employee, 3 years | D10: =IFERROR(D9/Assumptions!$B$6,"n/a") | E10: =IFERROR(E9/Assumptions!$B$6,"n/a")
A12: v2-LEAN — BUILD IN-HOUSE
B13: US$ | D13: ₱
A14: THREE-YEAR TOTAL | B14: =IFERROR(Costs!$E$34/Assumptions!$B$5,"n/a") | D14: =Costs!$E$34
A15: Per employee, 3 years | D15: =IFERROR(D14/Assumptions!$B$6,"n/a")
A17: THE COMPARISON
B18: Against the low band | C18: Against the high band
A19: How many times more expensive buying is | B19: =IFERROR(D9/D14,"n/a") | C19: =IFERROR(E9/D14,"n/a")
A20: Three-year cost difference | B20: =D9-D14 | C20: =E9-D14
A22: BREAK-EVEN — attributed internal hires needed over three years
A23: The framing that lands in a decision forum: how many internal hires each option must attract just to cover its own cost, at the avoided agency fee on Assumptions.
B24: Hires over 3 years | C24: Per year
A25: External platform — low band | B25: =IFERROR(D9/Assumptions!$B$34,"n/a") | C25: =IFERROR(B25/3,"n/a")
A26: External platform — high band | B26: =IFERROR(E9/Assumptions!$B$34,"n/a") | C26: =IFERROR(B26/3,"n/a")
A27: v2-lean | B27: =IFERROR(D14/Assumptions!$B$34,"n/a") | C27: =IFERROR(B27/3,"n/a")
A29: What buying gets you that this model does not price: a maintained skills ontology, pre-built HRIS and SSO connectors, SOC 2 / ISO 27001, a contractual support SLA, cross-company benchmarking, and a product roadmap. In-house, each of those is yours to build and keep building. The comparison above is cost only.

Sheet Benefits
A1: Benefits
A2: Two streams. They are not equally defensible — see the provenance column. Salaries are Payroll averages (Sep 2026); cost per hire is TA's 2025 file.
A4: DERIVED RATES
A5: Replacement cost per person | B5: =Assumptions!$B$35*Assumptions!$B$36 | H5: Non-mass annual basic × replacement %
A6: Cost of one vacant day | B6: =IFERROR(Assumptions!$B$42/Assumptions!$B$37,"n/a") | H6: Blended Band B/C annual basic ÷ working days
A7: Retention benefit per year | B7: =Assumptions!$B$39*Assumptions!$B$40*Benefits!$B$5 | H7: Participants × retention lift × replacement cost
A9: BY SCENARIO — annual, at steady state
A10: Scenario | B10: Fills/yr | C10: Hiring cost avoided (₱) | D10: Vacancy days (₱) | E10: ATTRIBUTED (₱) | F10: OWNED (₱) | G10: TOTAL (₱) | H10: What it depends on
A11: Conservative | B11: =Assumptions!$B$44 | C11: =B11*Assumptions!$B$34 | D11: =B11*Assumptions!$B$38*Benefits!$B$6 | E11: =C11+D11 | F11: =Benefits!$B$7 | G11: =E11+F11 | H11: Confirmed referrals in HC Connect
A12: Base | B12: =Assumptions!$B$45 | C12: =B12*Assumptions!$B$34 | D12: =B12*Assumptions!$B$38*Benefits!$B$6 | E12: =C12+D12 | F12: =Benefits!$B$7 | G12: =E12+F12 | H12: Confirmed referrals in HC Connect
A13: Optimistic | B13: =Assumptions!$B$46 | C13: =B13*Assumptions!$B$34 | D13: =B13*Assumptions!$B$38*Benefits!$B$6 | E13: =C13+D13 | F13: =Benefits!$B$7 | G13: =E13+F13 | H13: Confirmed referrals in HC Connect
A14: Base — retention excluded | B14: =Assumptions!$B$45 | C14: =B14*Assumptions!$B$34 | D14: =B14*Assumptions!$B$38*Benefits!$B$6 | E14: =C14+D14 | F14: 0 | G14: =E14+F14 | H14: Stress case: the softest input set to zero
A15: Retention only — zero fills | B15: 0 | C15: =B15*Assumptions!$B$34 | D15: =B15*Assumptions!$B$38*Benefits!$B$6 | E15: =C15+D15 | F15: =Benefits!$B$7 | G15: =E15+F15 | H15: Stress case: no attributed fills at all
A17: HOW MUCH EACH STREAM IS WORTH AS EVIDENCE
A18: ATTRIBUTED | B18: Avoided hiring cost and vacancy days on permanent roles. Exists ONLY because of the referral tracking — without a confirmed referral the hire is invisible in our data and belongs, as far as anyone can tell, to HC Connect. Requires HC Connect to add a "Growth Marketplace" source value; that commitment does not yet exist. At P113,522 a fill this stream is now roughly a fifth of the base-case benefit, so the case no longer stands on it alone.
A19: OWNED | B19: Retention among gig, DJI and service-offer participants. Needs no attribution, because the marketplace runs those end to end. It now carries most of the case, and the 3-point lift is still a discounted judgement rather than a measurement — which is why the year-one holdout is the gating instrument, not a nicety. See the stress rows above.
A20: EXCLUDED | B20: The value of gig output itself, skills built, and cross-functional network effects. All real, none reliably measurable, none needed to make the case.

Sheet Payback
A1: Payback — monthly cashflow
A2: Build lands in months 1–3 of its year, at IT's costed figure; benefits start in month 4. Feeds the CBA sheet.
A4: Month | B4: Year | C4: Build (₱) | D4: Run (₱) | E4: Cost (₱) | F4: Cum cost (₱) | G4: Conservative (₱) | H4: Base (₱) | I4: Optimistic (₱) | J4: Base no ret. (₱) | K4: Retention only (₱) | L4: Cum Conservative (₱) | M4: Cum Base (₱) | N4: Cum Optimistic (₱) | O4: Cum Base no ret. (₱) | P4: Cum Retention only (₱) | Q4: Hit Conservative | R4: Hit Base | S4: Hit Optimistic | T4: Hit Base no ret. | U4: Hit Retention only
A5: 1 | B5: =ROUNDUP(A5/12,0) | C5: =IF(A5<=3,Costs!$G$7/3,IF(AND(A5>=13,A5<=15),Costs!$G$8/3,0)) | D5: =IF(B5=1,Costs!$B$28/12,Costs!$C$28/12) | E5: =C5+D5 | F5: =E5 | G5: =IF(A5<=3,0,IF(B5=1,Benefits!$G$11*Assumptions!$B$41/9,Benefits!$G$11/12)) | H5: =IF(A5<=3,0,IF(B5=1,Benefits!$G$12*Assumptions!$B$41/9,Benefits!$G$12/12)) | I5: =IF(A5<=3,0,IF(B5=1,Benefits!$G$13*Assumptions!$B$41/9,Benefits!$G$13/12)) | J5: =IF(A5<=3,0,IF(B5=1,Benefits!$G$14*Assumptions!$B$41/9,Benefits!$G$14/12)) | K5: =IF(A5<=3,0,IF(B5=1,Benefits!$G$15*Assumptions!$B$41/9,Benefits!$G$15/12)) | L5: =G5 | M5: =H5 | N5: =I5 | O5: =J5 | P5: =K5 | Q5: =IF(L5>=F5,A5,"") | R5: =IF(M5>=F5,A5,"") | S5: =IF(N5>=F5,A5,"") | T5: =IF(O5>=F5,A5,"") | U5: =IF(P5>=F5,A5,"")
A6: 2 | B6: =ROUNDUP(A6/12,0) | C6: =IF(A6<=3,Costs!$G$7/3,IF(AND(A6>=13,A6<=15),Costs!$G$8/3,0)) | D6: =IF(B6=1,Costs!$B$28/12,Costs!$C$28/12) | E6: =C6+D6 | F6: =F5+E6 | G6: =IF(A6<=3,0,IF(B6=1,Benefits!$G$11*Assumptions!$B$41/9,Benefits!$G$11/12)) | H6: =IF(A6<=3,0,IF(B6=1,Benefits!$G$12*Assumptions!$B$41/9,Benefits!$G$12/12)) | I6: =IF(A6<=3,0,IF(B6=1,Benefits!$G$13*Assumptions!$B$41/9,Benefits!$G$13/12)) | J6: =IF(A6<=3,0,IF(B6=1,Benefits!$G$14*Assumptions!$B$41/9,Benefits!$G$14/12)) | K6: =IF(A6<=3,0,IF(B6=1,Benefits!$G$15*Assumptions!$B$41/9,Benefits!$G$15/12)) | L6: =L5+G6 | M6: =M5+H6 | N6: =N5+I6 | O6: =O5+J6 | P6: =P5+K6 | Q6: =IF(L6>=F6,A6,"") | R6: =IF(M6>=F6,A6,"") | S6: =IF(N6>=F6,A6,"") | T6: =IF(O6>=F6,A6,"") | U6: =IF(P6>=F6,A6,"")
A7: 3 | B7: =ROUNDUP(A7/12,0) | C7: =IF(A7<=3,Costs!$G$7/3,IF(AND(A7>=13,A7<=15),Costs!$G$8/3,0)) | D7: =IF(B7=1,Costs!$B$28/12,Costs!$C$28/12) | E7: =C7+D7 | F7: =F6+E7 | G7: =IF(A7<=3,0,IF(B7=1,Benefits!$G$11*Assumptions!$B$41/9,Benefits!$G$11/12)) | H7: =IF(A7<=3,0,IF(B7=1,Benefits!$G$12*Assumptions!$B$41/9,Benefits!$G$12/12)) | I7: =IF(A7<=3,0,IF(B7=1,Benefits!$G$13*Assumptions!$B$41/9,Benefits!$G$13/12)) | J7: =IF(A7<=3,0,IF(B7=1,Benefits!$G$14*Assumptions!$B$41/9,Benefits!$G$14/12)) | K7: =IF(A7<=3,0,IF(B7=1,Benefits!$G$15*Assumptions!$B$41/9,Benefits!$G$15/12)) | L7: =L6+G7 | M7: =M6+H7 | N7: =N6+I7 | O7: =O6+J7 | P7: =P6+K7 | Q7: =IF(L7>=F7,A7,"") | R7: =IF(M7>=F7,A7,"") | S7: =IF(N7>=F7,A7,"") | T7: =IF(O7>=F7,A7,"") | U7: =IF(P7>=F7,A7,"")
A8: 4 | B8: =ROUNDUP(A8/12,0) | C8: =IF(A8<=3,Costs!$G$7/3,IF(AND(A8>=13,A8<=15),Costs!$G$8/3,0)) | D8: =IF(B8=1,Costs!$B$28/12,Costs!$C$28/12) | E8: =C8+D8 | F8: =F7+E8 | G8: =IF(A8<=3,0,IF(B8=1,Benefits!$G$11*Assumptions!$B$41/9,Benefits!$G$11/12)) | H8: =IF(A8<=3,0,IF(B8=1,Benefits!$G$12*Assumptions!$B$41/9,Benefits!$G$12/12)) | I8: =IF(A8<=3,0,IF(B8=1,Benefits!$G$13*Assumptions!$B$41/9,Benefits!$G$13/12)) | J8: =IF(A8<=3,0,IF(B8=1,Benefits!$G$14*Assumptions!$B$41/9,Benefits!$G$14/12)) | K8: =IF(A8<=3,0,IF(B8=1,Benefits!$G$15*Assumptions!$B$41/9,Benefits!$G$15/12)) | L8: =L7+G8 | M8: =M7+H8 | N8: =N7+I8 | O8: =O7+J8 | P8: =P7+K8 | Q8: =IF(L8>=F8,A8,"") | R8: =IF(M8>=F8,A8,"") | S8: =IF(N8>=F8,A8,"") | T8: =IF(O8>=F8,A8,"") | U8: =IF(P8>=F8,A8,"")
A9: 5 | B9: =ROUNDUP(A9/12,0) | C9: =IF(A9<=3,Costs!$G$7/3,IF(AND(A9>=13,A9<=15),Costs!$G$8/3,0)) | D9: =IF(B9=1,Costs!$B$28/12,Costs!$C$28/12) | E9: =C9+D9 | F9: =F8+E9 | G9: =IF(A9<=3,0,IF(B9=1,Benefits!$G$11*Assumptions!$B$41/9,Benefits!$G$11/12)) | H9: =IF(A9<=3,0,IF(B9=1,Benefits!$G$12*Assumptions!$B$41/9,Benefits!$G$12/12)) | I9: =IF(A9<=3,0,IF(B9=1,Benefits!$G$13*Assumptions!$B$41/9,Benefits!$G$13/12)) | J9: =IF(A9<=3,0,IF(B9=1,Benefits!$G$14*Assumptions!$B$41/9,Benefits!$G$14/12)) | K9: =IF(A9<=3,0,IF(B9=1,Benefits!$G$15*Assumptions!$B$41/9,Benefits!$G$15/12)) | L9: =L8+G9 | M9: =M8+H9 | N9: =N8+I9 | O9: =O8+J9 | P9: =P8+K9 | Q9: =IF(L9>=F9,A9,"") | R9: =IF(M9>=F9,A9,"") | S9: =IF(N9>=F9,A9,"") | T9: =IF(O9>=F9,A9,"") | U9: =IF(P9>=F9,A9,"")
A10: 6 | B10: =ROUNDUP(A10/12,0) | C10: =IF(A10<=3,Costs!$G$7/3,IF(AND(A10>=13,A10<=15),Costs!$G$8/3,0)) | D10: =IF(B10=1,Costs!$B$28/12,Costs!$C$28/12) | E10: =C10+D10 | F10: =F9+E10 | G10: =IF(A10<=3,0,IF(B10=1,Benefits!$G$11*Assumptions!$B$41/9,Benefits!$G$11/12)) | H10: =IF(A10<=3,0,IF(B10=1,Benefits!$G$12*Assumptions!$B$41/9,Benefits!$G$12/12)) | I10: =IF(A10<=3,0,IF(B10=1,Benefits!$G$13*Assumptions!$B$41/9,Benefits!$G$13/12)) | J10: =IF(A10<=3,0,IF(B10=1,Benefits!$G$14*Assumptions!$B$41/9,Benefits!$G$14/12)) | K10: =IF(A10<=3,0,IF(B10=1,Benefits!$G$15*Assumptions!$B$41/9,Benefits!$G$15/12)) | L10: =L9+G10 | M10: =M9+H10 | N10: =N9+I10 | O10: =O9+J10 | P10: =P9+K10 | Q10: =IF(L10>=F10,A10,"") | R10: =IF(M10>=F10,A10,"") | S10: =IF(N10>=F10,A10,"") | T10: =IF(O10>=F10,A10,"") | U10: =IF(P10>=F10,A10,"")
A11: 7 | B11: =ROUNDUP(A11/12,0) | C11: =IF(A11<=3,Costs!$G$7/3,IF(AND(A11>=13,A11<=15),Costs!$G$8/3,0)) | D11: =IF(B11=1,Costs!$B$28/12,Costs!$C$28/12) | E11: =C11+D11 | F11: =F10+E11 | G11: =IF(A11<=3,0,IF(B11=1,Benefits!$G$11*Assumptions!$B$41/9,Benefits!$G$11/12)) | H11: =IF(A11<=3,0,IF(B11=1,Benefits!$G$12*Assumptions!$B$41/9,Benefits!$G$12/12)) | I11: =IF(A11<=3,0,IF(B11=1,Benefits!$G$13*Assumptions!$B$41/9,Benefits!$G$13/12)) | J11: =IF(A11<=3,0,IF(B11=1,Benefits!$G$14*Assumptions!$B$41/9,Benefits!$G$14/12)) | K11: =IF(A11<=3,0,IF(B11=1,Benefits!$G$15*Assumptions!$B$41/9,Benefits!$G$15/12)) | L11: =L10+G11 | M11: =M10+H11 | N11: =N10+I11 | O11: =O10+J11 | P11: =P10+K11 | Q11: =IF(L11>=F11,A11,"") | R11: =IF(M11>=F11,A11,"") | S11: =IF(N11>=F11,A11,"") | T11: =IF(O11>=F11,A11,"") | U11: =IF(P11>=F11,A11,"")
A12: 8 | B12: =ROUNDUP(A12/12,0) | C12: =IF(A12<=3,Costs!$G$7/3,IF(AND(A12>=13,A12<=15),Costs!$G$8/3,0)) | D12: =IF(B12=1,Costs!$B$28/12,Costs!$C$28/12) | E12: =C12+D12 | F12: =F11+E12 | G12: =IF(A12<=3,0,IF(B12=1,Benefits!$G$11*Assumptions!$B$41/9,Benefits!$G$11/12)) | H12: =IF(A12<=3,0,IF(B12=1,Benefits!$G$12*Assumptions!$B$41/9,Benefits!$G$12/12)) | I12: =IF(A12<=3,0,IF(B12=1,Benefits!$G$13*Assumptions!$B$41/9,Benefits!$G$13/12)) | J12: =IF(A12<=3,0,IF(B12=1,Benefits!$G$14*Assumptions!$B$41/9,Benefits!$G$14/12)) | K12: =IF(A12<=3,0,IF(B12=1,Benefits!$G$15*Assumptions!$B$41/9,Benefits!$G$15/12)) | L12: =L11+G12 | M12: =M11+H12 | N12: =N11+I12 | O12: =O11+J12 | P12: =P11+K12 | Q12: =IF(L12>=F12,A12,"") | R12: =IF(M12>=F12,A12,"") | S12: =IF(N12>=F12,A12,"") | T12: =IF(O12>=F12,A12,"") | U12: =IF(P12>=F12,A12,"")
A13: 9 | B13: =ROUNDUP(A13/12,0) | C13: =IF(A13<=3,Costs!$G$7/3,IF(AND(A13>=13,A13<=15),Costs!$G$8/3,0)) | D13: =IF(B13=1,Costs!$B$28/12,Costs!$C$28/12) | E13: =C13+D13 | F13: =F12+E13 | G13: =IF(A13<=3,0,IF(B13=1,Benefits!$G$11*Assumptions!$B$41/9,Benefits!$G$11/12)) | H13: =IF(A13<=3,0,IF(B13=1,Benefits!$G$12*Assumptions!$B$41/9,Benefits!$G$12/12)) | I13: =IF(A13<=3,0,IF(B13=1,Benefits!$G$13*Assumptions!$B$41/9,Benefits!$G$13/12)) | J13: =IF(A13<=3,0,IF(B13=1,Benefits!$G$14*Assumptions!$B$41/9,Benefits!$G$14/12)) | K13: =IF(A13<=3,0,IF(B13=1,Benefits!$G$15*Assumptions!$B$41/9,Benefits!$G$15/12)) | L13: =L12+G13 | M13: =M12+H13 | N13: =N12+I13 | O13: =O12+J13 | P13: =P12+K13 | Q13: =IF(L13>=F13,A13,"") | R13: =IF(M13>=F13,A13,"") | S13: =IF(N13>=F13,A13,"") | T13: =IF(O13>=F13,A13,"") | U13: =IF(P13>=F13,A13,"")
A14: 10 | B14: =ROUNDUP(A14/12,0) | C14: =IF(A14<=3,Costs!$G$7/3,IF(AND(A14>=13,A14<=15),Costs!$G$8/3,0)) | D14: =IF(B14=1,Costs!$B$28/12,Costs!$C$28/12) | E14: =C14+D14 | F14: =F13+E14 | G14: =IF(A14<=3,0,IF(B14=1,Benefits!$G$11*Assumptions!$B$41/9,Benefits!$G$11/12)) | H14: =IF(A14<=3,0,IF(B14=1,Benefits!$G$12*Assumptions!$B$41/9,Benefits!$G$12/12)) | I14: =IF(A14<=3,0,IF(B14=1,Benefits!$G$13*Assumptions!$B$41/9,Benefits!$G$13/12)) | J14: =IF(A14<=3,0,IF(B14=1,Benefits!$G$14*Assumptions!$B$41/9,Benefits!$G$14/12)) | K14: =IF(A14<=3,0,IF(B14=1,Benefits!$G$15*Assumptions!$B$41/9,Benefits!$G$15/12)) | L14: =L13+G14 | M14: =M13+H14 | N14: =N13+I14 | O14: =O13+J14 | P14: =P13+K14 | Q14: =IF(L14>=F14,A14,"") | R14: =IF(M14>=F14,A14,"") | S14: =IF(N14>=F14,A14,"") | T14: =IF(O14>=F14,A14,"") | U14: =IF(P14>=F14,A14,"")
A15: 11 | B15: =ROUNDUP(A15/12,0) | C15: =IF(A15<=3,Costs!$G$7/3,IF(AND(A15>=13,A15<=15),Costs!$G$8/3,0)) | D15: =IF(B15=1,Costs!$B$28/12,Costs!$C$28/12) | E15: =C15+D15 | F15: =F14+E15 | G15: =IF(A15<=3,0,IF(B15=1,Benefits!$G$11*Assumptions!$B$41/9,Benefits!$G$11/12)) | H15: =IF(A15<=3,0,IF(B15=1,Benefits!$G$12*Assumptions!$B$41/9,Benefits!$G$12/12)) | I15: =IF(A15<=3,0,IF(B15=1,Benefits!$G$13*Assumptions!$B$41/9,Benefits!$G$13/12)) | J15: =IF(A15<=3,0,IF(B15=1,Benefits!$G$14*Assumptions!$B$41/9,Benefits!$G$14/12)) | K15: =IF(A15<=3,0,IF(B15=1,Benefits!$G$15*Assumptions!$B$41/9,Benefits!$G$15/12)) | L15: =L14+G15 | M15: =M14+H15 | N15: =N14+I15 | O15: =O14+J15 | P15: =P14+K15 | Q15: =IF(L15>=F15,A15,"") | R15: =IF(M15>=F15,A15,"") | S15: =IF(N15>=F15,A15,"") | T15: =IF(O15>=F15,A15,"") | U15: =IF(P15>=F15,A15,"")
A16: 12 | B16: =ROUNDUP(A16/12,0) | C16: =IF(A16<=3,Costs!$G$7/3,IF(AND(A16>=13,A16<=15),Costs!$G$8/3,0)) | D16: =IF(B16=1,Costs!$B$28/12,Costs!$C$28/12) | E16: =C16+D16 | F16: =F15+E16 | G16: =IF(A16<=3,0,IF(B16=1,Benefits!$G$11*Assumptions!$B$41/9,Benefits!$G$11/12)) | H16: =IF(A16<=3,0,IF(B16=1,Benefits!$G$12*Assumptions!$B$41/9,Benefits!$G$12/12)) | I16: =IF(A16<=3,0,IF(B16=1,Benefits!$G$13*Assumptions!$B$41/9,Benefits!$G$13/12)) | J16: =IF(A16<=3,0,IF(B16=1,Benefits!$G$14*Assumptions!$B$41/9,Benefits!$G$14/12)) | K16: =IF(A16<=3,0,IF(B16=1,Benefits!$G$15*Assumptions!$B$41/9,Benefits!$G$15/12)) | L16: =L15+G16 | M16: =M15+H16 | N16: =N15+I16 | O16: =O15+J16 | P16: =P15+K16 | Q16: =IF(L16>=F16,A16,"") | R16: =IF(M16>=F16,A16,"") | S16: =IF(N16>=F16,A16,"") | T16: =IF(O16>=F16,A16,"") | U16: =IF(P16>=F16,A16,"")
A17: 13 | B17: =ROUNDUP(A17/12,0) | C17: =IF(A17<=3,Costs!$G$7/3,IF(AND(A17>=13,A17<=15),Costs!$G$8/3,0)) | D17: =IF(B17=1,Costs!$B$28/12,Costs!$C$28/12) | E17: =C17+D17 | F17: =F16+E17 | G17: =IF(A17<=3,0,IF(B17=1,Benefits!$G$11*Assumptions!$B$41/9,Benefits!$G$11/12)) | H17: =IF(A17<=3,0,IF(B17=1,Benefits!$G$12*Assumptions!$B$41/9,Benefits!$G$12/12)) | I17: =IF(A17<=3,0,IF(B17=1,Benefits!$G$13*Assumptions!$B$41/9,Benefits!$G$13/12)) | J17: =IF(A17<=3,0,IF(B17=1,Benefits!$G$14*Assumptions!$B$41/9,Benefits!$G$14/12)) | K17: =IF(A17<=3,0,IF(B17=1,Benefits!$G$15*Assumptions!$B$41/9,Benefits!$G$15/12)) | L17: =L16+G17 | M17: =M16+H17 | N17: =N16+I17 | O17: =O16+J17 | P17: =P16+K17 | Q17: =IF(L17>=F17,A17,"") | R17: =IF(M17>=F17,A17,"") | S17: =IF(N17>=F17,A17,"") | T17: =IF(O17>=F17,A17,"") | U17: =IF(P17>=F17,A17,"")
... A40: 36 | B40: =ROUNDUP(A40/12,0) | C40: =IF(A40<=3,Costs!$G$7/3,IF(AND(A40>=13,A40<=15),Costs!$G$8/3,0)) | D40: =IF(B40=1,Costs!$B$28/12,Costs!$C$28/12) | E40: =C40+D40 | F40: =F39+E40 | G40: =IF(A40<=3,0,IF(B40=1,Benefits!$G$11*Assumptions!$B$41/9,Benefits!$G$11/12)) | H40: =IF(A40<=3,0,IF(B40=1,Benefits!$G$12*Assumptions!$B$41/9,Benefits!$G$12/12)) | I40: =IF(A40<=3,0,IF(B40=1,Benefits!$G$13*Assumptions!$B$41/9,Benefits!$G$13/12)) | J40: =IF(A40<=3,0,IF(B40=1,Benefits!$G$14*Assumptions!$B$41/9,Benefits!$G$14/12)) | K40: =IF(A40<=3,0,IF(B40=1,Benefits!$G$15*Assumptions!$B$41/9,Benefits!$G$15/12)) | L40: =L39+G40 | M40: =M39+H40 | N40: =N39+I40 | O40: =O39+J40 | P40: =P39+K40 | Q40: =IF(L40>=F40,A40,"") | R40: =IF(M40>=F40,A40,"") | S40: =IF(N40>=F40,A40,"") | T40: =IF(O40>=F40,A40,"") | U40: =IF(P40>=F40,A40,"")
A42: Payback month | Q42: =IF(COUNT(Q5:Q40)=0,"none",MIN(Q5:Q40)) | R42: =IF(COUNT(R5:R40)=0,"none",MIN(R5:R40)) | S42: =IF(COUNT(S5:S40)=0,"none",MIN(S5:S40)) | T42: =IF(COUNT(T5:T40)=0,"none",MIN(T5:T40)) | U42: =IF(COUNT(U5:U40)=0,"none",MIN(U5:U40))

Sheet CBA
A1: Cost-benefit analysis
A2: Three years, discounted at the rate on Assumptions. Year-1 benefit ramped for build and adoption.
A4: THE CASE
A5: Scenario | B5: Y1 benefit | C5: Y2 benefit | D5: Y3 benefit | E5: 3-yr benefit | F5: 3-yr cost | G5: Net | H5: BCR | I5: NPV | J5: Payback
A6: Conservative — 2 fills/yr | B6: =Benefits!$G$11*Assumptions!$B$41 | C6: =Benefits!$G$11 | D6: =Benefits!$G$11 | E6: =SUM(B6:D6) | F6: =Costs!$E$34 | G6: =E6-F6 | H6: =IFERROR(E6/F6,"n/a") | I6: =(B6-Costs!$B$34)/(1+Assumptions!$B$7)^1+(C6-Costs!$C$34)/(1+Assumptions!$B$7)^2+(D6-Costs!$D$34)/(1+Assumptions!$B$7)^3 | J6: =Payback!Q42
A7: Base — 4 fills/yr | B7: =Benefits!$G$12*Assumptions!$B$41 | C7: =Benefits!$G$12 | D7: =Benefits!$G$12 | E7: =SUM(B7:D7) | F7: =Costs!$E$34 | G7: =E7-F7 | H7: =IFERROR(E7/F7,"n/a") | I7: =(B7-Costs!$B$34)/(1+Assumptions!$B$7)^1+(C7-Costs!$C$34)/(1+Assumptions!$B$7)^2+(D7-Costs!$D$34)/(1+Assumptions!$B$7)^3 | J7: =Payback!R42
A8: Optimistic — 7 fills/yr | B8: =Benefits!$G$13*Assumptions!$B$41 | C8: =Benefits!$G$13 | D8: =Benefits!$G$13 | E8: =SUM(B8:D8) | F8: =Costs!$E$34 | G8: =E8-F8 | H8: =IFERROR(E8/F8,"n/a") | I8: =(B8-Costs!$B$34)/(1+Assumptions!$B$7)^1+(C8-Costs!$C$34)/(1+Assumptions!$B$7)^2+(D8-Costs!$D$34)/(1+Assumptions!$B$7)^3 | J8: =Payback!S42
A9: Base, retention excluded | B9: =Benefits!$G$14*Assumptions!$B$41 | C9: =Benefits!$G$14 | D9: =Benefits!$G$14 | E9: =SUM(B9:D9) | F9: =Costs!$E$34 | G9: =E9-F9 | H9: =IFERROR(E9/F9,"n/a") | I9: =(B9-Costs!$B$34)/(1+Assumptions!$B$7)^1+(C9-Costs!$C$34)/(1+Assumptions!$B$7)^2+(D9-Costs!$D$34)/(1+Assumptions!$B$7)^3 | J9: =Payback!T42
A10: Retention only, zero fills | B10: =Benefits!$G$15*Assumptions!$B$41 | C10: =Benefits!$G$15 | D10: =Benefits!$G$15 | E10: =SUM(B10:D10) | F10: =Costs!$E$34 | G10: =E10-F10 | H10: =IFERROR(E10/F10,"n/a") | I10: =(B10-Costs!$B$34)/(1+Assumptions!$B$7)^1+(C10-Costs!$C$34)/(1+Assumptions!$B$7)^2+(D10-Costs!$D$34)/(1+Assumptions!$B$7)^3 | J10: =Payback!U42
A12: READING THIS
A13: Read the retention-excluded row before quoting the base case. Pricing a fill at what TA actually spends — P113,522, not the old P350,000 — moves the weight of this case onto retention, which is roughly six-sevenths of the base-case benefit. Remove mass operations, refuse the vacancy-day credit, or lose attribution entirely and the ratio still clears 3. Remove retention and it does not. That is the one measurement worth designing properly before the build starts.
A15: BREAK-EVEN
B16: Value | D16: Method
A17: Attributed fills per year to break even | B17: =IFERROR(Costs!$E$34/((1+1+Assumptions!$B$41)*(Assumptions!$B$34+Assumptions!$B$38*Benefits!$B$6)),"n/a") | D17: Three-year cost ÷ (ramped years × value per attributed fill, P113,522). Retention excluded entirely — this is the fills-only bar.
A18: As a share of ~60 internal requisitions a year | B18: =IFERROR(B17/60,"n/a")
A19: Years for retention alone to repay the cost | B19: =IF(Benefits!$B$7<=0,"never",Costs!$E$34/Benefits!$B$7) | D19: Three-year cost ÷ annual retention benefit. Assumes zero attributed fills.

Sheet Sensitivity
A1: Sensitivity
A2: What moves the answer. Base case unless stated.
A4: COST SENSITIVITIES
A5: Change | B5: 3-year cost | C5: vs base | D5: Read
A6: Base case — as modelled | B6: =Costs!$E$34 | C6: =B6-Costs!$E$34 | D6: The Costs sheet total.
A7: Developer rate +25% | B7: =Costs!$E$34+(Assumptions!$B$18+Assumptions!$B$24)*Assumptions!$B$12*0.25*(1+Assumptions!$B$8) | C7: =B7-Costs!$E$34 | D7: The single largest swing in the build. Validate against your own rate card first.
A8: Build effort doubles | B8: =Costs!$E$34+(Costs!$D$12+Costs!$D$18) | C8: =B8-Costs!$E$34 | D8: Still far below the external-platform bands. See Competition.
A9: Exchange rate ₱65/US$ | B9: =Costs!$E$34+(Assumptions!$B$27*12+0)*(65-Assumptions!$B$5) | C9: =B9-Costs!$E$34 | D9: Only the US$-denominated run lines move. Vendor bands move proportionally, so the comparison is unchanged.
A10: 0.25 FTE internal ownership from year 2 | B10: =Costs!$E$34+0.25*900000*2 | C10: =B10-Costs!$E$34 | D10: Excluded from the base case and material. The most under-estimated line in any build-versus-buy — include it before comparing.
A11: Cancel the year-2 referral engine | B11: =Costs!$E$34-Costs!$D$18 | C11: =B11-Costs!$E$34 | D11: Only viable if referral volume never justifies it. Decide on year-one data.
A13: BENEFIT SENSITIVITIES
A14: Change | B14: 3-yr benefit | C14: BCR | D14: Read
A15: Base case — as modelled | B15: =Benefits!$G$12*(2+Assumptions!$B$41) | C15: =IFERROR(B15/Costs!$E$34,"n/a") | D15: Both streams, base scenario.
A16: Retention lift is zero | B16: =Benefits!$G$14*(2+Assumptions!$B$41) | C16: =IFERROR(B16/Costs!$E$34,"n/a") | D16: The softest input removed entirely. At the corrected P113,522 per fill this is where the case fails — the reason the retention holdout is now a gate.
A17: No attributed fills at all | B17: =Benefits!$G$15*(2+Assumptions!$B$41) | C17: =IFERROR(B17/Costs!$E$34,"n/a") | D17: HC Connect declines the source field, or nobody clicks through. Retention alone carries it.
A18: Participants halve to 60 | B18: =(Benefits!$E$12+Assumptions!$B$39/2*Assumptions!$B$40*Benefits!$B$5)*(2+Assumptions!$B$41) | C18: =IFERROR(B18/Costs!$E$34,"n/a") | D18: Retention scales linearly with participation.
A19: Hiring cost avoided only — no vacancy-day credit | B19: =(Benefits!$B$12*Assumptions!$B$34+Benefits!$B$7)*(2+Assumptions!$B$41) | C19: =IFERROR(B19/Costs!$E$34,"n/a") | D19: Treats the 37 vacancy days as unrecoverable. The harder floor on the attributed stream.
A21: The two that actually decide this: whether the retention lift is real (it is a judgement here, and a holdout is the only way to settle it — promote a random half of open requisitions for a quarter and compare), and whether HC Connect adds the source field (without it only the owned stream is defensible).
